Workbook

Sheet Start Here
A1: The Lanark Pantry — Operations & Costing Workbook
A2: Blue text = inputs. Black text = formulas. Use the tabs from left to right.
A4: Suggested workflow
A5: 1) Fill Ingredients & Packaging with pack sizes + costs (this powers all cost lookups).
A6: 2) Fill Suppliers + Customers/Wholesalers.
A7: 3) For each product tab, complete the BOM (bill of materials) and pricing section.
A8: 4) Log each production run in Production Batches (COGS/unit auto).
A9: 5) Log wholesale/direct sales in Sales Orders. Use Dashboard for quick totals.

Sheet Dashboard
A1: Dashboard
A2: This pulls totals from Production Batches, Sales Orders, and Inventory.
A4: COGS (this month) | C4: Revenue (this month)
A5: =IFERROR(SUMIFS('Production Batches'!K:K,'Production Batches'!B:B,">="&EOMONTH(TODAY(),-1)+1,'Production Batches'!B:B,"<="&EOMONTH(TODAY(),0)),0) -> 0 | C5: =IFERROR(SUMIFS('Sales Orders'!L:L,'Sales Orders'!B:B,">="&EOMONTH(TODAY(),-1)+1,'Sales Orders'!B:B,"<="&EOMONTH(TODAY(),0)),0) -> 0
A7: Gross profit (this month) | C7: Gross margin % (this month)
A8: =D5-B5 -> 0 | C8: =IFERROR((D5-B5)/D5,0) -> 0
A10: Inventory value (est.) | C10: Top customer (YTD)
A11: =IFERROR(SUM(Inventory!H:H),0) -> 0 | C11: =IFERROR(INDEX(Customers!B:B, MATCH(MAX(Customers!M:M),Customers!M:M,0)),"") -> 0
A13: Tip: Keep Production Batches + Sales Orders up to date for the dashboard to stay accurate.
A15: Website-aligned update
A16: Product range now reflects the live shop: fruit/veg boxes, bought-in staples, selected jars and kitchen extras.
A17: Older jar/ferment/salt products have been retained as Post-launch / Second stage in Product Index and Website Product Range.
A18: Updated 2026-05-30

Sheet Labels
A1: SKU | B1: Display name | C1: Website category | D1: Pack size | E1: Unit | F1: Website price (£) | G1: Listing tag | H1: Front/shop short description | I1: Secondary copy / pairing | J1: Allergen callouts | K1: Storage | L1: Date mark | M1: Producer/source | N1: Stage
A2: WPB | B2: Weekly Produce Box | C2: Weekly fruit and veg boxes | E2: box | F2: 20 | G2: Smaller box | H2: Smaller flexible weekly produce base; contents shift seasonally. | N2: Launch
A3: FPB | B3: Family Produce Box | C3: Weekly fruit and veg boxes | E3: box | F3: 30 | G3: Larger box | H3: Larger weekly produce box for households cooking most nights; contents shift seasonally. | N3: Launch
A4: BBC-BB | B4: Bold Bean Co Queen Butter Beans | C4: Cupboard staples | D4: 540 | E4: g | F4: 3.5 | G4: Regular staple | H4: Large soft butter beans for fast dinners, traybakes and simple weeknight cooking. | I4: Works well with tomatoes, harissa, greens and roast vegetables. | N4: Launch
A5: BBC-CP | B5: Bold Bean Co Queen Chickpeas | C5: Cupboard staples | D5: 540 | E5: g | F5: 3.5 | G5: Regular staple | H5: Tender jarred chickpeas for quick bowls, traybakes and easy dinners. | I5: Works well with harissa, tomatoes, herbs, couscous and tahini. | N5: Launch
A6: BBC-WB | B6: Bold Bean Co Queen White Beans | C6: Cupboard staples | D6: 540 | E6: g | F6: 3.5 | G6: Regular staple | H6: Creamy white beans for soups, greens, tomato dishes and simple bowls. | I6: Works well with garlic, lemon, miso, herbs and soft vegetables. | N6: Launch
A7: MUT-POLPA | B7: Mutti Polpa Tomatoes | C7: Cupboard staples | D7: 400 | E7: g | F7: 1.5 | G7: Regular staple | H7: Finely chopped tomatoes for sauces, beans and quick one-pan meals. | I7: One of the most useful bases to keep in the cupboard. | N7: Launch
A8: BUC | B8: Bucatini | C8: Cupboard staples | D8: 500 | E8: g | F8: 3.5 | G8: Regular staple | H8: Hollow pasta with extra bite for tomato sauces, pesto and creamy dishes. | I8: A satisfying pasta shape that still feels easy to cook. | N8: Launch
A9: CAS | B9: Casarecce Pasta | C9: Cupboard staples | D9: 500 | E9: g | F9: 2.95 | G9: Regular staple | H9: Useful pasta shape for pesto, roasted vegetables, greens and jarred sauces. | I9: Good when you want something simple but a little more interesting. | N9: Launch
A10: ORZ | B10: Orzo Pasta | C10: Cupboard staples | D10: 500 | E10: g | F10: 2.75 | G10: Regular staple | H10: Small pasta for quick bowls, soups, traybakes and easy midweek cooking. | I10: Useful when you want something fast, flexible and not too heavy. | N10: Launch
A11: GC | B11: Giant Couscous | C11: Cupboard staples | D11: 500 | E11: g | F11: 3.75 | G11: Regular staple | H11: Flexible cupboard staple that works warm or cold. | I11: Good with roast vegetables, herbs, dressings and punchy jars. | N11: Launch
A12: POL | B12: Polenta | C12: Cupboard staples | D12: 500 | E12: g | F12: 4 | G12: Regular staple | H12: Soft comforting base for roasted vegetables, beans and simple suppers. | I12: Naturally gluten-free and useful for quick savoury bowls. | N12: Launch
A13: PUY | B13: Puy Lentils | C13: Cupboard staples | D13: 500 | E13: g | F13: 4.5 | G13: Regular staple | H13: Structured lentils for warm salads, batch cooking, bowls and sides. | I13: Useful to cook ahead and keep in the fridge for quick meals. | N13: Launch
A14: RICE-SG | B14: Short Grain Rice | C14: Cupboard staples | D14: 500 | E14: g | F14: 4.75 | G14: Regular staple | H14: Versatile rice for risotto-style cooking, simple sides and puddings. | I14: A flexible cupboard basic that works sweet or savoury. | N14: Launch
A15: FAR | B15: Farro | C15: Cupboard staples | D15: 500 | E15: g | F15: 5.5 | G15: Regular staple | H15: Nutty chewy grain for bowls, salads and simple vegetable-led dinners. | I15: Works well with roast vegetables, herbs, soft cheeses and harissa. | N15: Launch
A16: SWP | B16: Sorrel & Walnut Pesto | C16: Sauces and jars | F16: 4.5 | G16: Flavour jar | H16: Fresh savoury jar for pasta, potatoes or roasted vegetables. | I16: Add when you want something quick and green in the fridge. | J16: Contains WALNUTS. | N16: Launch
A17: RH | B17: Rose Harissa | C17: Sauces and jars | F17: 5.25 | G17: Flavour jar | H17: Gently spiced jar for beans, grains and roast vegetables. | I17: A small spoonful brings warmth without making dinner complicated. | N17: Launch
A18: SCAR | B18: Salted Caramel Sauce | C18: Sauces and jars | F18: 5 | G18: Flavour jar | H18: Rich sweet jar for desserts, yoghurt, toast or baking. | I18: A simple cupboard treat to add when you want one. | N18: Launch
A19: DCH | B19: Dark Chocolate & Hazelnut Spread | C19: Sauces and jars | F19: 5 | G19: Flavour jar | H19: Darker chocolate spread for toast, baking or simple puddings. | I19: An easy sweet extra to keep in the cupboard. | J19: Contains HAZELNUTS. May contain other allergens depending on ingredient spec. | N19: Launch
A20: ALM | B20: Almonds | C20: Kitchen extras | D20: 500 | E20: g | F20: 4.95 | G20: Extra | H20: Everyday nut for baking, breakfast, salads and simple cooking. | J20: Contains ALMONDS. | N20: Launch
A21: WAL | B21: Walnuts | C21: Kitchen extras | D21: 500 | E21: g | F21: 5.5 | G21: Extra | H21: Savoury-leaning extra for grains, leaves, roast veg and cheese. | J21: Contains WALNUTS. | N21: Launch
A22: HAZ | B22: Hazelnuts | C22: Kitchen extras | D22: 500 | E22: g | F22: 5.95 | G22: Extra | H22: Slightly special nut for sweet things, baking and darker flavours. | J22: Contains HAZELNUTS. | N22: Launch
A23: CASH | B23: Cashews | C23: Kitchen extras | D23: 500 | E23: g | F23: 4.25 | G23: Extra | H23: Soft useful nut for snacking, cooking and adding richness. | J23: Contains CASHEWS. | N23: Launch
A24: WG | B24: Wild Greens & Sea Herb Pesto | C24: Post-launch jars | D24: 190 | E24: g | G24: Post-launch | H24: Not currently listed on website. Retained for second stage. | N24: Post-launch
A25: MC | B25: Mango, Chilli & Whisky Chutney | C25: Post-launch jars | D25: 190 | E25: g | G25: Post-launch | H25: Not currently listed on website. Retained for second stage. | N25: Post-launch
A26: KIM | B26: Scottish Kimchi (Apple & Kelp) | C26: Post-launch ferments | D26: 190 | E26: g | G26: Post-launch | H26: Not currently listed on website. Retained for second stage. | N26: Post-launch
A27: SK | B27: Beetroot, Juniper & Black Pepper Sauerkraut | C27: Post-launch ferments | D27: 190 | E27: g | G27: Post-launch | H27: Not currently listed on website. Retained for second stage. | N27: Post-launch
A28: HHCS | B28: Salted Heather Honey Caramel Sauce (Oat) | C28: Post-launch jars | D28: 190 | E28: g | G28: Post-launch | H28: Website lists simplified Salted Caramel Sauce; old heather honey/oat variant retained for second stage. | N28: Post-launch
A29: GM | B29: Gin & Juniper Berry Marmalade | C29: Post-launch jars | D29: 190 | E29: g | G29: Post-launch | H29: Not currently listed on website. Retained for second stage. | N29: Post-launch
A30: VP | B30: Vegetable Stock Paste | C30: Post-launch jars | D30: 190 | E30: g | G30: Post-launch | H30: Listed in earlier spreadsheet but not currently on website. | N30: Post-launch
A31: GS | B31: Gochujang Sauce | C31: Post-launch jars | D31: 190 | E31: g | G31: Post-launch | H31: Listed in earlier spreadsheet but not currently on website. | N31: Post-launch
A32: RS | B32: Rosemary & Scottish Sea Salt | C32: Post-launch salts | G32: Post-launch | H32: Listed in earlier product bible but not currently on website. | N32: Post-launch
A33: CSS | B33: Seaweed, Sesame & Garlic Coastal Salt | C33: Post-launch salts | G33: Post-launch | H33: Listed in earlier product bible but not currently on website. | N33: Post-launch
A34: SCHS | B34: Smoked Chilli & Heather Salt | C34: Post-launch salts | G34: Post-launch | H34: Listed in earlier product bible but not currently on website. | N34: Post-launch
A35: RC | B35: Raspberry & Cardamom Compote | C35: Post-launch jars | D35: 190 | E35: g | G35: Post-launch | H35: Listed in earlier product bible but not currently on website. | N35: Post-launch

Sheet Products Index
A1: SKU | B1: Product name | C1: Category | D1: Jar/pack size | E1: Target batch size / bought-in qty | F1: Default wholesale (£) | G1: RRP (£) | H1: Stage | I1: Notes
A2: WPB | B2: Weekly Produce Box | C2: Weekly fruit and veg boxes | D2: box | G2: 20 | H2: Launch | I2: Smaller flexible weekly produce base; contents shift seasonally.
A3: FPB | B3: Family Produce Box | C3: Weekly fruit and veg boxes | D3: box | G3: 30 | H3: Launch | I3: Larger weekly produce box for households cooking most nights; contents shift seasonally.
A4: BBC-BB | B4: Bold Bean Co Queen Butter Beans | C4: Cupboard staples | D4: 540 g | G4: 3.5 | H4: Launch | I4: Large soft butter beans for fast dinners, traybakes and simple weeknight cooking.
A5: BBC-CP | B5: Bold Bean Co Queen Chickpeas | C5: Cupboard staples | D5: 540 g | G5: 3.5 | H5: Launch | I5: Tender jarred chickpeas for quick bowls, traybakes and easy dinners.
A6: BBC-WB | B6: Bold Bean Co Queen White Beans | C6: Cupboard staples | D6: 540 g | G6: 3.5 | H6: Launch | I6: Creamy white beans for soups, greens, tomato dishes and simple bowls.
A7: MUT-POLPA | B7: Mutti Polpa Tomatoes | C7: Cupboard staples | D7: 400 g | G7: 1.5 | H7: Launch | I7: Finely chopped tomatoes for sauces, beans and quick one-pan meals.
A8: BUC | B8: Bucatini | C8: Cupboard staples | D8: 500 g | G8: 3.5 | H8: Launch | I8: Hollow pasta with extra bite for tomato sauces, pesto and creamy dishes.
A9: CAS | B9: Casarecce Pasta | C9: Cupboard staples | D9: 500 g | G9: 2.95 | H9: Launch | I9: Useful pasta shape for pesto, roasted vegetables, greens and jarred sauces.
A10: ORZ | B10: Orzo Pasta | C10: Cupboard staples | D10: 500 g | G10: 2.75 | H10: Launch | I10: Small pasta for quick bowls, soups, traybakes and easy midweek cooking.
A11: GC | B11: Giant Couscous | C11: Cupboard staples | D11: 500 g | G11: 3.75 | H11: Launch | I11: Flexible cupboard staple that works warm or cold.
A12: POL | B12: Polenta | C12: Cupboard staples | D12: 500 g | G12: 4 | H12: Launch | I12: Soft comforting base for roasted vegetables, beans and simple suppers.
A13: PUY | B13: Puy Lentils | C13: Cupboard staples | D13: 500 g | G13: 4.5 | H13: Launch | I13: Structured lentils for warm salads, batch cooking, bowls and sides.
... A15: FAR | B15: Farro | C15: Cupboard staples | D15: 500 g | G15: 5.5 | H15: Launch | I15: Nutty chewy grain for bowls, salads and simple vegetable-led dinners.
A16: SWP | B16: Sorrel & Walnut Pesto | C16: Sauces and jars | G16: 4.5 | H16: Launch | I16: Fresh savoury jar for pasta, potatoes or roasted vegetables.
A17: RH | B17: Rose Harissa | C17: Sauces and jars | G17: 5.25 | H17: Launch | I17: Gently spiced jar for beans, grains and roast vegetables.
A18: SCAR | B18: Salted Caramel Sauce | C18: Sauces and jars | G18: 5 | H18: Launch | I18: Rich sweet jar for desserts, yoghurt, toast or baking.
A19: DCH | B19: Dark Chocolate & Hazelnut Spread | C19: Sauces and jars | G19: 5 | H19: Launch | I19: Darker chocolate spread for toast, baking or simple puddings.
A20: ALM | B20: Almonds | C20: Kitchen extras | D20: 500 g | G20: 4.95 | H20: Launch | I20: Everyday nut for baking, breakfast, salads and simple cooking.
A21: WAL | B21: Walnuts | C21: Kitchen extras | D21: 500 g | G21: 5.5 | H21: Launch | I21: Savoury-leaning extra for grains, leaves, roast veg and cheese.
A22: HAZ | B22: Hazelnuts | C22: Kitchen extras | D22: 500 g | G22: 5.95 | H22: Launch | I22: Slightly special nut for sweet things, baking and darker flavours.
A23: CASH | B23: Cashews | C23: Kitchen extras | D23: 500 g | G23: 4.25 | H23: Launch | I23: Soft useful nut for snacking, cooking and adding richness.
A24: WG | B24: Wild Greens & Sea Herb Pesto | C24: Post-launch jars | D24: 190 g | H24: Post-launch | I24: Not currently listed on website. Retained for second stage.
A25: MC | B25: Mango, Chilli & Whisky Chutney | C25: Post-launch jars | D25: 190 g | H25: Post-launch | I25: Not currently listed on website. Retained for second stage.
A26: KIM | B26: Scottish Kimchi (Apple & Kelp) | C26: Post-launch ferments | D26: 190 g | H26: Post-launch | I26: Not currently listed on website. Retained for second stage.
A27: SK | B27: Beetroot, Juniper & Black Pepper Sauerkraut | C27: Post-launch ferments | D27: 190 g | H27: Post-launch | I27: Not currently listed on website. Retained for second stage.
A28: HHCS | B28: Salted Heather Honey Caramel Sauce (Oat) | C28: Post-launch jars | D28: 190 g | H28: Post-launch | I28: Website lists simplified Salted Caramel Sauce; old heather honey/oat variant retained for second stage.
A29: GM | B29: Gin & Juniper Berry Marmalade | C29: Post-launch jars | D29: 190 g | H29: Post-launch | I29: Not currently listed on website. Retained for second stage.
A30: VP | B30: Vegetable Stock Paste | C30: Post-launch jars | D30: 190 g | H30: Post-launch | I30: Listed in earlier spreadsheet but not currently on website.
A31: GS | B31: Gochujang Sauce | C31: Post-launch jars | D31: 190 g | H31: Post-launch | I31: Listed in earlier spreadsheet but not currently on website.
A32: RS | B32: Rosemary & Scottish Sea Salt | C32: Post-launch salts | H32: Post-launch | I32: Listed in earlier product bible but not currently on website.
A33: CSS | B33: Seaweed, Sesame & Garlic Coastal Salt | C33: Post-launch salts | H33: Post-launch | I33: Listed in earlier product bible but not currently on website.
A34: SCHS | B34: Smoked Chilli & Heather Salt | C34: Post-launch salts | H34: Post-launch | I34: Listed in earlier product bible but not currently on website.
A35: RC | B35: Raspberry & Cardamom Compote | C35: Post-launch jars | D35: 190 g | H35: Post-launch | I35: Listed in earlier product bible but not currently on website.

Sheet Ingredients & Packaging
A1: Item type | B1: Item name | C1: Supplier ID | D1: Supplier | E1: Pack size | F1: Unit | G1: Pack cost (£) | H1: Cost per unit (£) | I1: Allergen? | J1: Lead time (days) | K1: Active? | L1: Notes
A2: Ingredient | B2: Dried chillies | E2: 1000 | F2: g | G2: 0 | H2: =IFERROR(G2/E2,0) -> 0 | I2: No | K2: Yes
A3: Ingredient | B3: Olive oil | E3: 5000 | F3: ml | G3: 0 | H3: =IFERROR(G3/E3,0) -> 0 | I3: No | K3: Yes
A4: Ingredient | B4: Rapeseed oil | E4: 5000 | F4: ml | G4: 0 | H4: =IFERROR(G4/E4,0) -> 0 | I4: No | K4: Yes
A5: Ingredient | B5: Sugar | E5: 1000 | F5: g | G5: 0 | H5: =IFERROR(G5/E5,0) -> 0 | I5: No | K5: Yes
A6: Packaging | B6: Square jar 190g | E6: 1 | F6: each | G6: 0.9 | H6: =IFERROR(G6/E6,0) -> 0.9 | I6: No | K6: Yes
A7: Packaging | B7: Square jar 200g | E7: 1 | F7: each | G7: 0 | H7: =IFERROR(G7/E7,0) -> 0 | I7: No | K7: Yes
A8: Packaging | B8: Square jar 290g | E8: 1 | F8: each | G8: 0 | H8: =IFERROR(G8/E8,0) -> 0 | I8: No | K8: Yes
A9: Packaging | B9: Square jar 400g | E9: 1 | F9: each | G9: 0 | H9: =IFERROR(G9/E9,0) -> 0 | I9: No | K9: Yes
A10: Packaging | B10: Lid | E10: 1 | F10: each | G10: 0 | H10: =IFERROR(G10/E10,0) -> 0 | I10: No | K10: Yes
A11: Label | B11: Wrap label (3-panel) | E11: 1 | F11: each | G11: 0 | H11: =IFERROR(G11/E11,0) -> 0 | I11: No | K11: Yes

Sheet Suppliers
A1: Supplier ID | B1: Supplier name | C1: Type | D1: Contact | E1: Email | F1: Phone | G1: Address | H1: Lead time (days) | I1: MOQ | J1: Payment terms | K1: Notes | L1: Active?

Sheet Customers
A1: Customer ID | B1: Customer name | C1: Type | D1: Contact | E1: Email | F1: Phone | G1: Address | H1: Delivery terms | I1: Payment terms | J1: Default discount % | K1: Notes | L1: Active? | M1: YTD revenue (£) | N1: YTD units
M2: =IFERROR(SUMIFS('Sales Orders'!L:L,'Sales Orders'!D:D,$A2,'Sales Orders'!B:B,">="&DATE(YEAR(TODAY()),1,1),'Sales Orders'!B:B,"<="&TODAY()),0) -> 0 | N2: =IFERROR(SUMIFS('Sales Orders'!H:H,'Sales Orders'!D:D,$A2,'Sales Orders'!B:B,">="&DATE(YEAR(TODAY()),1,1),'Sales Orders'!B:B,"<="&TODAY()),0) -> 0
M3: =IFERROR(SUMIFS('Sales Orders'!L:L,'Sales Orders'!D:D,$A3,'Sales Orders'!B:B,">="&DATE(YEAR(TODAY()),1,1),'Sales Orders'!B:B,"<="&TODAY()),0) -> 0 | N3: =IFERROR(SUMIFS('Sales Orders'!H:H,'Sales Orders'!D:D,$A3,'Sales Orders'!B:B,">="&DATE(YEAR(TODAY()),1,1),'Sales Orders'!B:B,"<="&TODAY()),0) -> 0
M4: =IFERROR(SUMIFS('Sales Orders'!L:L,'Sales Orders'!D:D,$A4,'Sales Orders'!B:B,">="&DATE(YEAR(TODAY()),1,1),'Sales Orders'!B:B,"<="&TODAY()),0) -> 0 | N4: =IFERROR(SUMIFS('Sales Orders'!H:H,'Sales Orders'!D:D,$A4,'Sales Orders'!B:B,">="&DATE(YEAR(TODAY()),1,1),'Sales Orders'!B:B,"<="&TODAY()),0) -> 0
M5: =IFERROR(SUMIFS('Sales Orders'!L:L,'Sales Orders'!D:D,$A5,'Sales Orders'!B:B,">="&DATE(YEAR(TODAY()),1,1),'Sales Orders'!B:B,"<="&TODAY()),0) -> 0 | N5: =IFERROR(SUMIFS('Sales Orders'!H:H,'Sales Orders'!D:D,$A5,'Sales Orders'!B:B,">="&DATE(YEAR(TODAY()),1,1),'Sales Orders'!B:B,"<="&TODAY()),0) -> 0
M6: =IFERROR(SUMIFS('Sales Orders'!L:L,'Sales Orders'!D:D,$A6,'Sales Orders'!B:B,">="&DATE(YEAR(TODAY()),1,1),'Sales Orders'!B:B,"<="&TODAY()),0) -> 0 | N6: =IFERROR(SUMIFS('Sales Orders'!H:H,'Sales Orders'!D:D,$A6,'Sales Orders'!B:B,">="&DATE(YEAR(TODAY()),1,1),'Sales Orders'!B:B,"<="&TODAY()),0) -> 0
M7: =IFERROR(SUMIFS('Sales Orders'!L:L,'Sales Orders'!D:D,$A7,'Sales Orders'!B:B,">="&DATE(YEAR(TODAY()),1,1),'Sales Orders'!B:B,"<="&TODAY()),0) -> 0 | N7: =IFERROR(SUMIFS('Sales Orders'!H:H,'Sales Orders'!D:D,$A7,'Sales Orders'!B:B,">="&DATE(YEAR(TODAY()),1,1),'Sales Orders'!B:B,"<="&TODAY()),0) -> 0
M8: =IFERROR(SUMIFS('Sales Orders'!L:L,'Sales Orders'!D:D,$A8,'Sales Orders'!B:B,">="&DATE(YEAR(TODAY()),1,1),'Sales Orders'!B:B,"<="&TODAY()),0) -> 0 | N8: =IFERROR(SUMIFS('Sales Orders'!H:H,'Sales Orders'!D:D,$A8,'Sales Orders'!B:B,">="&DATE(YEAR(TODAY()),1,1),'Sales Orders'!B:B,"<="&TODAY()),0) -> 0
M9: =IFERROR(SUMIFS('Sales Orders'!L:L,'Sales Orders'!D:D,$A9,'Sales Orders'!B:B,">="&DATE(YEAR(TODAY()),1,1),'Sales Orders'!B:B,"<="&TODAY()),0) -> 0 | N9: =IFERROR(SUMIFS('Sales Orders'!H:H,'Sales Orders'!D:D,$A9,'Sales Orders'!B:B,">="&DATE(YEAR(TODAY()),1,1),'Sales Orders'!B:B,"<="&TODAY()),0) -> 0
M10: =IFERROR(SUMIFS('Sales Orders'!L:L,'Sales Orders'!D:D,$A10,'Sales Orders'!B:B,">="&DATE(YEAR(TODAY()),1,1),'Sales Orders'!B:B,"<="&TODAY()),0) -> 0 | N10: =IFERROR(SUMIFS('Sales Orders'!H:H,'Sales Orders'!D:D,$A10,'Sales Orders'!B:B,">="&DATE(YEAR(TODAY()),1,1),'Sales Orders'!B:B,"<="&TODAY()),0) -> 0
M11: =IFERROR(SUMIFS('Sales Orders'!L:L,'Sales Orders'!D:D,$A11,'Sales Orders'!B:B,">="&DATE(YEAR(TODAY()),1,1),'Sales Orders'!B:B,"<="&TODAY()),0) -> 0 | N11: =IFERROR(SUMIFS('Sales Orders'!H:H,'Sales Orders'!D:D,$A11,'Sales Orders'!B:B,">="&DATE(YEAR(TODAY()),1,1),'Sales Orders'!B:B,"<="&TODAY()),0) -> 0
M12: =IFERROR(SUMIFS('Sales Orders'!L:L,'Sales Orders'!D:D,$A12,'Sales Orders'!B:B,">="&DATE(YEAR(TODAY()),1,1),'Sales Orders'!B:B,"<="&TODAY()),0) -> 0 | N12: =IFERROR(SUMIFS('Sales Orders'!H:H,'Sales Orders'!D:D,$A12,'Sales Orders'!B:B,">="&DATE(YEAR(TODAY()),1,1),'Sales Orders'!B:B,"<="&TODAY()),0) -> 0
M13: =IFERROR(SUMIFS('Sales Orders'!L:L,'Sales Orders'!D:D,$A13,'Sales Orders'!B:B,">="&DATE(YEAR(TODAY()),1,1),'Sales Orders'!B:B,"<="&TODAY()),0) -> 0 | N13: =IFERROR(SUMIFS('Sales Orders'!H:H,'Sales Orders'!D:D,$A13,'Sales Orders'!B:B,">="&DATE(YEAR(TODAY()),1,1),'Sales Orders'!B:B,"<="&TODAY()),0) -> 0
... M301: =IFERROR(SUMIFS('Sales Orders'!L:L,'Sales Orders'!D:D,$A301,'Sales Orders'!B:B,">="&DATE(YEAR(TODAY()),1,1),'Sales Orders'!B:B,"<="&TODAY()),0) -> 0 | N301: =IFERROR(SUMIFS('Sales Orders'!H:H,'Sales Orders'!D:D,$A301,'Sales Orders'!B:B,">="&DATE(YEAR(TODAY()),1,1),'Sales Orders'!B:B,"<="&TODAY()),0) -> 0

Sheet Price Lists
A1: Customer ID | B1: Customer name | C1: SKU | D1: Product | E1: Wholesale price (£) | F1: RRP (£) | G1: Discount % | H1: Net price (£) | I1: MOQ (units) | J1: Lead time (days) | K1: Active? | L1: Notes
B2: =IFERROR(VLOOKUP(A2,Customers!$A:$B,2,FALSE),"") | D2: =IFERROR(VLOOKUP(C2,'Products Index'!$A:$B,2,FALSE),"") | H2: =IFERROR(E2*(1-G2),0) -> 0
B3: =IFERROR(VLOOKUP(A3,Customers!$A:$B,2,FALSE),"") | D3: =IFERROR(VLOOKUP(C3,'Products Index'!$A:$B,2,FALSE),"") | H3: =IFERROR(E3*(1-G3),0) -> 0
B4: =IFERROR(VLOOKUP(A4,Customers!$A:$B,2,FALSE),"") | D4: =IFERROR(VLOOKUP(C4,'Products Index'!$A:$B,2,FALSE),"") | H4: =IFERROR(E4*(1-G4),0) -> 0
B5: =IFERROR(VLOOKUP(A5,Customers!$A:$B,2,FALSE),"") | D5: =IFERROR(VLOOKUP(C5,'Products Index'!$A:$B,2,FALSE),"") | H5: =IFERROR(E5*(1-G5),0) -> 0
B6: =IFERROR(VLOOKUP(A6,Customers!$A:$B,2,FALSE),"") | D6: =IFERROR(VLOOKUP(C6,'Products Index'!$A:$B,2,FALSE),"") | H6: =IFERROR(E6*(1-G6),0) -> 0
B7: =IFERROR(VLOOKUP(A7,Customers!$A:$B,2,FALSE),"") | D7: =IFERROR(VLOOKUP(C7,'Products Index'!$A:$B,2,FALSE),"") | H7: =IFERROR(E7*(1-G7),0) -> 0
B8: =IFERROR(VLOOKUP(A8,Customers!$A:$B,2,FALSE),"") | D8: =IFERROR(VLOOKUP(C8,'Products Index'!$A:$B,2,FALSE),"") | H8: =IFERROR(E8*(1-G8),0) -> 0
B9: =IFERROR(VLOOKUP(A9,Customers!$A:$B,2,FALSE),"") | D9: =IFERROR(VLOOKUP(C9,'Products Index'!$A:$B,2,FALSE),"") | H9: =IFERROR(E9*(1-G9),0) -> 0
B10: =IFERROR(VLOOKUP(A10,Customers!$A:$B,2,FALSE),"") | D10: =IFERROR(VLOOKUP(C10,'Products Index'!$A:$B,2,FALSE),"") | H10: =IFERROR(E10*(1-G10),0) -> 0
B11: =IFERROR(VLOOKUP(A11,Customers!$A:$B,2,FALSE),"") | D11: =IFERROR(VLOOKUP(C11,'Products Index'!$A:$B,2,FALSE),"") | H11: =IFERROR(E11*(1-G11),0) -> 0
B12: =IFERROR(VLOOKUP(A12,Customers!$A:$B,2,FALSE),"") | D12: =IFERROR(VLOOKUP(C12,'Products Index'!$A:$B,2,FALSE),"") | H12: =IFERROR(E12*(1-G12),0) -> 0
B13: =IFERROR(VLOOKUP(A13,Customers!$A:$B,2,FALSE),"") | D13: =IFERROR(VLOOKUP(C13,'Products Index'!$A:$B,2,FALSE),"") | H13: =IFERROR(E13*(1-G13),0) -> 0
... B501: =IFERROR(VLOOKUP(A501,Customers!$A:$B,2,FALSE),"") | D501: =IFERROR(VLOOKUP(C501,'Products Index'!$A:$B,2,FALSE),"") | H501: =IFERROR(E501*(1-G501),0) -> 0

Sheet Overheads
A1: Overheads (monthly)
A2: Enter monthly overheads. Used for optional allocation in Production Batches.
A4: Month | B4: Rent (£) | C4: Utilities (£) | D4: Insurance (£) | E4: Labour (£) | F4: Transport (£) | G4: Other (£) | H4: Total (£)
H5: =SUM(B5:G5) -> 0
H6: =SUM(B6:G6) -> 0
H7: =SUM(B7:G7) -> 0
H8: =SUM(B8:G8) -> 0
H9: =SUM(B9:G9) -> 0
H10: =SUM(B10:G10) -> 0
H11: =SUM(B11:G11) -> 0
H12: =SUM(B12:G12) -> 0
H13: =SUM(B13:G13) -> 0
H14: =SUM(B14:G14) -> 0
H15: =SUM(B15:G15) -> 0
H16: =SUM(B16:G16) -> 0
... H64: =SUM(B64:G64) -> 0

Sheet Rose Harissa Paste
A1: Rose Harissa Paste
A2: SKU: RH | Category: Savoury
A4: Product details | E4: Label & marketing fields
A5: Jar size (g) | B5: 190 | E5: Ingredients statement | F5: Dried red chillies, olive oil, garlic, tomato purée, lemon juice, spices (caraway, cumin, coriander), sea salt, rose water.
A6: Target batch size (g) | B6: 2200 | E6: Allergen advice | F6: For allergens, see ingredients in bold.
A7: Batch yield actual (g) | B7: 2200 | E7: 3 uses (short) | F7: • Stir 1–2 tsp into soups, stews or beans. • Mix with olive oil + lemon for a salad dressing. • Rub over chicken, lamb, cauliflower or halloumi before roasting.
A8: Units per batch | B8: =IFERROR(B7/B5,0) -> 11.578947 | E8: Recipe idea (short) | F8: Harissa Roast Cauliflower & Chickpeas Toss cauliflower florets + 2 tins chickpeas with 3 tbsp harissa + 3 tbsp olive oil + pinch salt. Roast 25–30 min at 220°C until charred. Finish with lemon juice.
A9: Shelf life unopened | E9: Web product blurb | F9: A punchy chilli paste with fragrant rose and warm spices.
A10: Storage instructions
A11: Allergens (bold on label)
A12: Net weight on label | B12: 190
A13: Notes
A15: Bill of Materials (BOM) — per target batch
A16: Component name | B16: Item type | C16: Qty | D16: Unit | E16: Cost/unit (£) | F16: Line cost (£) | G16: Waste % | H16: Cost w/ waste (£) | I16: Supplier/notes
A17: chillies | E17: =IFERROR(INDEX('Ingredients & Packaging'!$H:$H, MATCH(1, ('Ingredients & Packaging'!$B:$B=A17)*('Ingredients & Packaging'!$A:$A=B17),0)),0) -> 0 | F17: =IFERROR(C17*E17,0) -> 0 | H17: =IFERROR(F17*(1+G17),0) -> 0
A18: rapeseed oil | E18: =IFERROR(INDEX('Ingredients & Packaging'!$H:$H, MATCH(1, ('Ingredients & Packaging'!$B:$B=A18)*('Ingredients & Packaging'!$A:$A=B18),0)),0) -> 0 | F18: =IFERROR(C18*E18,0) -> 0 | H18: =IFERROR(F18*(1+G18),0) -> 0
A19: tomato puree | E19: =IFERROR(INDEX('Ingredients & Packaging'!$H:$H, MATCH(1, ('Ingredients & Packaging'!$B:$B=A19)*('Ingredients & Packaging'!$A:$A=B19),0)),0) -> 0 | F19: =IFERROR(C19*E19,0) -> 0 | H19: =IFERROR(F19*(1+G19),0) -> 0
A20: lemon juice | E20: =IFERROR(INDEX('Ingredients & Packaging'!$H:$H, MATCH(1, ('Ingredients & Packaging'!$B:$B=A20)*('Ingredients & Packaging'!$A:$A=B20),0)),0) -> 0 | F20: =IFERROR(C20*E20,0) -> 0 | H20: =IFERROR(F20*(1+G20),0) -> 0
A21: rose petals | E21: =IFERROR(INDEX('Ingredients & Packaging'!$H:$H, MATCH(1, ('Ingredients & Packaging'!$B:$B=A21)*('Ingredients & Packaging'!$A:$A=B21),0)),0) -> 0 | F21: =IFERROR(C21*E21,0) -> 0 | H21: =IFERROR(F21*(1+G21),0) -> 0
A22: garlic | E22: =IFERROR(INDEX('Ingredients & Packaging'!$H:$H, MATCH(1, ('Ingredients & Packaging'!$B:$B=A22)*('Ingredients & Packaging'!$A:$A=B22),0)),0) -> 0 | F22: =IFERROR(C22*E22,0) -> 0 | H22: =IFERROR(F22*(1+G22),0) -> 0
A23: spices | E23: =IFERROR(INDEX('Ingredients & Packaging'!$H:$H, MATCH(1, ('Ingredients & Packaging'!$B:$B=A23)*('Ingredients & Packaging'!$A:$A=B23),0)),0) -> 0 | F23: =IFERROR(C23*E23,0) -> 0 | H23: =IFERROR(F23*(1+G23),0) -> 0
A24: honey | E24: =IFERROR(INDEX('Ingredients & Packaging'!$H:$H, MATCH(1, ('Ingredients & Packaging'!$B:$B=A24)*('Ingredients & Packaging'!$A:$A=B24),0)),0) -> 0 | F24: =IFERROR(C24*E24,0) -> 0 | H24: =IFERROR(F24*(1+G24),0) -> 0
E25: =IFERROR(INDEX('Ingredients & Packaging'!$H:$H, MATCH(1, ('Ingredients & Packaging'!$B:$B=A25)*('Ingredients & Packaging'!$A:$A=B25),0)),0) -> 0 | F25: =IFERROR(C25*E25,0) -> 0 | H25: =IFERROR(F25*(1+G25),0) -> 0
E26: =IFERROR(INDEX('Ingredients & Packaging'!$H:$H, MATCH(1, ('Ingredients & Packaging'!$B:$B=A26)*('Ingredients & Packaging'!$A:$A=B26),0)),0) -> 0 | F26: =IFERROR(C26*E26,0) -> 0 | H26: =IFERROR(F26*(1+G26),0) -> 0
E27: =IFERROR(INDEX('Ingredients & Packaging'!$H:$H, MATCH(1, ('Ingredients & Packaging'!$B:$B=A27)*('Ingredients & Packaging'!$A:$A=B27),0)),0) -> 0 | F27: =IFERROR(C27*E27,0) -> 0 | H27: =IFERROR(F27*(1+G27),0) -> 0
E28: =IFERROR(INDEX('Ingredients & Packaging'!$H:$H, MATCH(1, ('Ingredients & Packaging'!$B:$B=A28)*('Ingredients & Packaging'!$A:$A=B28),0)),0) -> 0 | F28: =IFERROR(C28*E28,0) -> 0 | H28: =IFERROR(F28*(1+G28),0) -> 0
E29: =IFERROR(INDEX('Ingredients & Packaging'!$H:$H, MATCH(1, ('Ingredients & Packaging'!$B:$B=A29)*('Ingredients & Packaging'!$A:$A=B29),0)),0) -> 0 | F29: =IFERROR(C29*E29,0) -> 0 | H29: =IFERROR(F29*(1+G29),0) -> 0
E30: =IFERROR(INDEX('Ingredients & Packaging'!$H:$H, MATCH(1, ('Ingredients & Packaging'!$B:$B=A30)*('Ingredients & Packaging'!$A:$A=B30),0)),0) -> 0 | F30: =IFERROR(C30*E30,0) -> 0 | H30: =IFERROR(F30*(1+G30),0) -> 0
E31: =IFERROR(INDEX('Ingredients & Packaging'!$H:$H, MATCH(1, ('Ingredients & Packaging'!$B:$B=A31)*('Ingredients & Packaging'!$A:$A=B31),0)),0) -> 0 | F31: =IFERROR(C31*E31,0) -> 0 | H31: =IFERROR(F31*(1+G31),0) -> 0
E32: =IFERROR(INDEX('Ingredients & Packaging'!$H:$H, MATCH(1, ('Ingredients & Packaging'!$B:$B=A32)*('Ingredients & Packaging'!$A:$A=B32),0)),0) -> 0 | F32: =IFERROR(C32*E32,0) -> 0 | H32: =IFERROR(F32*(1+G32),0) -> 0
E33: =IFERROR(INDEX('Ingredients & Packaging'!$H:$H, MATCH(1, ('Ingredients & Packaging'!$B:$B=A33)*('Ingredients & Packaging'!$A:$A=B33),0)),0) -> 0 | F33: =IFERROR(C33*E33,0) -> 0 | H33: =IFERROR(F33*(1+G33),0) -> 0
E34: =IFERROR(INDEX('Ingredients & Packaging'!$H:$H, MATCH(1, ('Ingredients & Packaging'!$B:$B=A34)*('Ingredients & Packaging'!$A:$A=B34),0)),0) -> 0 | F34: =IFERROR(C34*E34,0) -> 0 | H34: =IFERROR(F34*(1+G34),0) -> 0
E35: =IFERROR(INDEX('Ingredients & Packaging'!$H:$H, MATCH(1, ('Ingredients & Packaging'!$B:$B=A35)*('Ingredients & Packaging'!$A:$A=B35),0)),0) -> 0 | F35: =IFERROR(C35*E35,0) -> 0 | H35: =IFERROR(F35*(1+G35),0) -> 0
E36: =IFERROR(INDEX('Ingredients & Packaging'!$H:$H, MATCH(1, ('Ingredients & Packaging'!$B:$B=A36)*('Ingredients & Packaging'!$A:$A=B36),0)),0) -> 0 | F36: =IFERROR(C36*E36,0) -> 0 | H36: =IFERROR(F36*(1+G36),0) -> 0
... E56: =IFERROR(INDEX('Ingredients & Packaging'!$H:$H, MATCH(1, ('Ingredients & Packaging'!$B:$B=A56)*('Ingredients & Packaging'!$A:$A=B56),0)),0) -> 0 | F56: =IFERROR(C56*E56,0) -> 0 | H56: =IFERROR(F56*(1+G56),0) -> 0
A58: Cost summary
A59: Total BOM cost (target batch) | B59: =SUM(H17:H56) -> 0
A60: COGS per jar (£) | B60: =IFERROR(B59/ B8,0) -> 0
A61: Target wholesale (£) | B61: =VLOOKUP("RH",'Products Index'!$A:$F,6,FALSE) -> 0
A62: RRP (£) | B62: =VLOOKUP("RH",'Products Index'!$A:$G,7,FALSE) -> 5.25
...

Sheet Wild Greens & Sea Herb Pesto
A1: Wild Greens & Sea Herb Pesto
A2: SKU: WG | Category: Savoury
A4: Product details | E4: Label & marketing fields
A5: Jar size (g) | B5: 190 | E5: Ingredients statement | F5: Wild greens (nettle, wild garlic, kale), Scottish cold-pressed rapeseed oil, CASHEW NUTS, pumpkin seeds, lemon juice, sea herbs (dulse), garlic, nutritional yeast, sea salt.
A6: Target batch size (g) | B6: 2200 | E6: Allergen advice | F6: For allergens, see ingredients in bold.
A7: Batch yield actual (g) | B7: 2200 | E7: 3 uses (short) | F7: • Toss through hot pasta with a splash of cooking water. • Spread in sandwiches or wraps. • Stir into mash or butter beans.
A8: Units per batch | B8: =IFERROR(B7/B5,0) -> 11.578947 | E8: Recipe idea (short) | F8: Sea‑Herb Pesto Pasta Cook 400g pasta. Toss with 4 tbsp pesto + 2–4 tbsp pasta water until glossy. Finish with lemon zest/juice and black pepper.
A9: Shelf life unopened | E9: Web product blurb | F9: A vivid green pesto with coastal dulse and toasted seeds.
A10: Storage instructions
A11: Allergens (bold on label)
A12: Net weight on label | B12: 190
A13: Notes
A15: Bill of Materials (BOM) — per target batch
A16: Component name | B16: Item type | C16: Qty | D16: Unit | E16: Cost/unit (£) | F16: Line cost (£) | G16: Waste % | H16: Cost w/ waste (£) | I16: Supplier/notes
A17: nettles | E17: =IFERROR(INDEX('Ingredients & Packaging'!$H:$H, MATCH(1, ('Ingredients & Packaging'!$B:$B=A17)*('Ingredients & Packaging'!$A:$A=B17),0)),0) -> 0 | F17: =IFERROR(C17*E17,0) -> 0 | H17: =IFERROR(F17*(1+G17),0) -> 0
A18: kale | E18: =IFERROR(INDEX('Ingredients & Packaging'!$H:$H, MATCH(1, ('Ingredients & Packaging'!$B:$B=A18)*('Ingredients & Packaging'!$A:$A=B18),0)),0) -> 0 | F18: =IFERROR(C18*E18,0) -> 0 | H18: =IFERROR(F18*(1+G18),0) -> 0
A19: walnuts | E19: =IFERROR(INDEX('Ingredients & Packaging'!$H:$H, MATCH(1, ('Ingredients & Packaging'!$B:$B=A19)*('Ingredients & Packaging'!$A:$A=B19),0)),0) -> 0 | F19: =IFERROR(C19*E19,0) -> 0 | H19: =IFERROR(F19*(1+G19),0) -> 0
A20: rapeseed oil | E20: =IFERROR(INDEX('Ingredients & Packaging'!$H:$H, MATCH(1, ('Ingredients & Packaging'!$B:$B=A20)*('Ingredients & Packaging'!$A:$A=B20),0)),0) -> 0 | F20: =IFERROR(C20*E20,0) -> 0 | H20: =IFERROR(F20*(1+G20),0) -> 0
A21: garlic | E21: =IFERROR(INDEX('Ingredients & Packaging'!$H:$H, MATCH(1, ('Ingredients & Packaging'!$B:$B=A21)*('Ingredients & Packaging'!$A:$A=B21),0)),0) -> 0 | F21: =IFERROR(C21*E21,0) -> 0 | H21: =IFERROR(F21*(1+G21),0) -> 0
A22: nutritional yeast | E22: =IFERROR(INDEX('Ingredients & Packaging'!$H:$H, MATCH(1, ('Ingredients & Packaging'!$B:$B=A22)*('Ingredients & Packaging'!$A:$A=B22),0)),0) -> 0 | F22: =IFERROR(C22*E22,0) -> 0 | H22: =IFERROR(F22*(1+G22),0) -> 0
A23: salt | E23: =IFERROR(INDEX('Ingredients & Packaging'!$H:$H, MATCH(1, ('Ingredients & Packaging'!$B:$B=A23)*('Ingredients & Packaging'!$A:$A=B23),0)),0) -> 0 | F23: =IFERROR(C23*E23,0) -> 0 | H23: =IFERROR(F23*(1+G23),0) -> 0
A24: dulse | E24: =IFERROR(INDEX('Ingredients & Packaging'!$H:$H, MATCH(1, ('Ingredients & Packaging'!$B:$B=A24)*('Ingredients & Packaging'!$A:$A=B24),0)),0) -> 0 | F24: =IFERROR(C24*E24,0) -> 0 | H24: =IFERROR(F24*(1+G24),0) -> 0
E25: =IFERROR(INDEX('Ingredients & Packaging'!$H:$H, MATCH(1, ('Ingredients & Packaging'!$B:$B=A25)*('Ingredients & Packaging'!$A:$A=B25),0)),0) -> 0 | F25: =IFERROR(C25*E25,0) -> 0 | H25: =IFERROR(F25*(1+G25),0) -> 0
E26: =IFERROR(INDEX('Ingredients & Packaging'!$H:$H, MATCH(1, ('Ingredients & Packaging'!$B:$B=A26)*('Ingredients & Packaging'!$A:$A=B26),0)),0) -> 0 | F26: =IFERROR(C26*E26,0) -> 0 | H26: =IFERROR(F26*(1+G26),0) -> 0
E27: =IFERROR(INDEX('Ingredients & Packaging'!$H:$H, MATCH(1, ('Ingredients & Packaging'!$B:$B=A27)*('Ingredients & Packaging'!$A:$A=B27),0)),0) -> 0 | F27: =IFERROR(C27*E27,0) -> 0 | H27: =IFERROR(F27*(1+G27),0) -> 0
E28: =IFERROR(INDEX('Ingredients & Packaging'!$H:$H, MATCH(1, ('Ingredients & Packaging'!$B:$B=A28)*('Ingredients & Packaging'!$A:$A=B28),0)),0) -> 0 | F28: =IFERROR(C28*E28,0) -> 0 | H28: =IFERROR(F28*(1+G28),0) -> 0
E29: =IFERROR(INDEX('Ingredients & Packaging'!$H:$H, MATCH(1, ('Ingredients & Packaging'!$B:$B=A29)*('Ingredients & Packaging'!$A:$A=B29),0)),0) -> 0 | F29: =IFERROR(C29*E29,0) -> 0 | H29: =IFERROR(F29*(1+G29),0) -> 0
E30: =IFERROR(INDEX('Ingredients & Packaging'!$H:$H, MATCH(1, ('Ingredients & Packaging'!$B:$B=A30)*('Ingredients & Packaging'!$A:$A=B30),0)),0) -> 0 | F30: =IFERROR(C30*E30,0) -> 0 | H30: =IFERROR(F30*(1+G30),0) -> 0
E31: =IFERROR(INDEX('Ingredients & Packaging'!$H:$H, MATCH(1, ('Ingredients & Packaging'!$B:$B=A31)*('Ingredients & Packaging'!$A:$A=B31),0)),0) -> 0 | F31: =IFERROR(C31*E31,0) -> 0 | H31: =IFERROR(F31*(1+G31),0) -> 0
E32: =IFERROR(INDEX('Ingredients & Packaging'!$H:$H, MATCH(1, ('Ingredients & Packaging'!$B:$B=A32)*('Ingredients & Packaging'!$A:$A=B32),0)),0) -> 0 | F32: =IFERROR(C32*E32,0) -> 0 | H32: =IFERROR(F32*(1+G32),0) -> 0
E33: =IFERROR(INDEX('Ingredients & Packaging'!$H:$H, MATCH(1, ('Ingredients & Packaging'!$B:$B=A33)*('Ingredients & Packaging'!$A:$A=B33),0)),0) -> 0 | F33: =IFERROR(C33*E33,0) -> 0 | H33: =IFERROR(F33*(1+G33),0) -> 0
E34: =IFERROR(INDEX('Ingredients & Packaging'!$H:$H, MATCH(1, ('Ingredients & Packaging'!$B:$B=A34)*('Ingredients & Packaging'!$A:$A=B34),0)),0) -> 0 | F34: =IFERROR(C34*E34,0) -> 0 | H34: =IFERROR(F34*(1+G34),0) -> 0
E35: =IFERROR(INDEX('Ingredients & Packaging'!$H:$H, MATCH(1, ('Ingredients & Packaging'!$B:$B=A35)*('Ingredients & Packaging'!$A:$A=B35),0)),0) -> 0 | F35: =IFERROR(C35*E35,0) -> 0 | H35: =IFERROR(F35*(1+G35),0) -> 0
E36: =IFERROR(INDEX('Ingredients & Packaging'!$H:$H, MATCH(1, ('Ingredients & Packaging'!$B:$B=A36)*('Ingredients & Packaging'!$A:$A=B36),0)),0) -> 0 | F36: =IFERROR(C36*E36,0) -> 0 | H36: =IFERROR(F36*(1+G36),0) -> 0
... E56: =IFERROR(INDEX('Ingredients & Packaging'!$H:$H, MATCH(1, ('Ingredients & Packaging'!$B:$B=A56)*('Ingredients & Packaging'!$A:$A=B56),0)),0) -> 0 | F56: =IFERROR(C56*E56,0) -> 0 | H56: =IFERROR(F56*(1+G56),0) -> 0
A58: Cost summary
A59: Total BOM cost (target batch) | B59: =SUM(H17:H56) -> 0
A60: COGS per jar (£) | B60: =IFERROR(B59/ B8,0) -> 0
A61: Target wholesale (£) | B61: =VLOOKUP("WG",'Products Index'!$A:$F,6,FALSE) -> 0
A62: RRP (£) | B62: =VLOOKUP("WG",'Products Index'!$A:$G,7,FALSE) -> 0
...

Sheet Mango, Chilli & Whisky Chutney
A1: Mango, Chilli & Whisky Chutney
A2: SKU: MC | Category: Savoury
A4: Product details | E4: Label & marketing fields
A5: Jar size (g) | B5: 190 | E5: Ingredients statement | F5: Mango (45%), onion, sugar, cider vinegar, Scottish whisky, chilli, ginger, MUSTARD seeds, spices, sea salt.
A6: Target batch size (g) | B6: 2200 | E6: Allergen advice | F6: For allergens, see ingredients in bold.
A7: Batch yield actual (g) | B7: 2200 | E7: 3 uses (short) | F7: • Serve with cheese, pork pies or ham. • Spoon into curries, dhal or lentil soups. • Glaze sausages, chicken or roasted squash.
A8: Units per batch | B8: =IFERROR(B7/B5,0) -> 11.578947 | E8: Recipe idea (short) | F8: Sticky Chutney Sausages Roast 12 sausages 25 min at 200°C. Warm 6 tbsp chutney + 1 tbsp vinegar; brush over. Return 8–10 min until sticky.
A9: Shelf life unopened | E9: Web product blurb | F9: A sweet, sticky chutney with chilli warmth and whisky depth.
A10: Storage instructions
A11: Allergens (bold on label)
A12: Net weight on label | B12: 190
A13: Notes
A15: Bill of Materials (BOM) — per target batch
A16: Component name | B16: Item type | C16: Qty | D16: Unit | E16: Cost/unit (£) | F16: Line cost (£) | G16: Waste % | H16: Cost w/ waste (£) | I16: Supplier/notes
A17: mango | E17: =IFERROR(INDEX('Ingredients & Packaging'!$H:$H, MATCH(1, ('Ingredients & Packaging'!$B:$B=A17)*('Ingredients & Packaging'!$A:$A=B17),0)),0) -> 0 | F17: =IFERROR(C17*E17,0) -> 0 | H17: =IFERROR(F17*(1+G17),0) -> 0
A18: chillies | E18: =IFERROR(INDEX('Ingredients & Packaging'!$H:$H, MATCH(1, ('Ingredients & Packaging'!$B:$B=A18)*('Ingredients & Packaging'!$A:$A=B18),0)),0) -> 0 | F18: =IFERROR(C18*E18,0) -> 0 | H18: =IFERROR(F18*(1+G18),0) -> 0
A19: whisky | E19: =IFERROR(INDEX('Ingredients & Packaging'!$H:$H, MATCH(1, ('Ingredients & Packaging'!$B:$B=A19)*('Ingredients & Packaging'!$A:$A=B19),0)),0) -> 0 | F19: =IFERROR(C19*E19,0) -> 0 | H19: =IFERROR(F19*(1+G19),0) -> 0
A20: onion | E20: =IFERROR(INDEX('Ingredients & Packaging'!$H:$H, MATCH(1, ('Ingredients & Packaging'!$B:$B=A20)*('Ingredients & Packaging'!$A:$A=B20),0)),0) -> 0 | F20: =IFERROR(C20*E20,0) -> 0 | H20: =IFERROR(F20*(1+G20),0) -> 0
A21: sugar | E21: =IFERROR(INDEX('Ingredients & Packaging'!$H:$H, MATCH(1, ('Ingredients & Packaging'!$B:$B=A21)*('Ingredients & Packaging'!$A:$A=B21),0)),0) -> 0 | F21: =IFERROR(C21*E21,0) -> 0 | H21: =IFERROR(F21*(1+G21),0) -> 0
A22: apple cider vinegar | E22: =IFERROR(INDEX('Ingredients & Packaging'!$H:$H, MATCH(1, ('Ingredients & Packaging'!$B:$B=A22)*('Ingredients & Packaging'!$A:$A=B22),0)),0) -> 0 | F22: =IFERROR(C22*E22,0) -> 0 | H22: =IFERROR(F22*(1+G22),0) -> 0
A23: ginger | E23: =IFERROR(INDEX('Ingredients & Packaging'!$H:$H, MATCH(1, ('Ingredients & Packaging'!$B:$B=A23)*('Ingredients & Packaging'!$A:$A=B23),0)),0) -> 0 | F23: =IFERROR(C23*E23,0) -> 0 | H23: =IFERROR(F23*(1+G23),0) -> 0
E24: =IFERROR(INDEX('Ingredients & Packaging'!$H:$H, MATCH(1, ('Ingredients & Packaging'!$B:$B=A24)*('Ingredients & Packaging'!$A:$A=B24),0)),0) -> 0 | F24: =IFERROR(C24*E24,0) -> 0 | H24: =IFERROR(F24*(1+G24),0) -> 0
E25: =IFERROR(INDEX('Ingredients & Packaging'!$H:$H, MATCH(1, ('Ingredients & Packaging'!$B:$B=A25)*('Ingredients & Packaging'!$A:$A=B25),0)),0) -> 0 | F25: =IFERROR(C25*E25,0) -> 0 | H25: =IFERROR(F25*(1+G25),0) -> 0
E26: =IFERROR(INDEX('Ingredients & Packaging'!$H:$H, MATCH(1, ('Ingredients & Packaging'!$B:$B=A26)*('Ingredients & Packaging'!$A:$A=B26),0)),0) -> 0 | F26: =IFERROR(C26*E26,0) -> 0 | H26: =IFERROR(F26*(1+G26),0) -> 0
E27: =IFERROR(INDEX('Ingredients & Packaging'!$H:$H, MATCH(1, ('Ingredients & Packaging'!$B:$B=A27)*('Ingredients & Packaging'!$A:$A=B27),0)),0) -> 0 | F27: =IFERROR(C27*E27,0) -> 0 | H27: =IFERROR(F27*(1+G27),0) -> 0
E28: =IFERROR(INDEX('Ingredients & Packaging'!$H:$H, MATCH(1, ('Ingredients & Packaging'!$B:$B=A28)*('Ingredients & Packaging'!$A:$A=B28),0)),0) -> 0 | F28: =IFERROR(C28*E28,0) -> 0 | H28: =IFERROR(F28*(1+G28),0) -> 0
E29: =IFERROR(INDEX('Ingredients & Packaging'!$H:$H, MATCH(1, ('Ingredients & Packaging'!$B:$B=A29)*('Ingredients & Packaging'!$A:$A=B29),0)),0) -> 0 | F29: =IFERROR(C29*E29,0) -> 0 | H29: =IFERROR(F29*(1+G29),0) -> 0
E30: =IFERROR(INDEX('Ingredients & Packaging'!$H:$H, MATCH(1, ('Ingredients & Packaging'!$B:$B=A30)*('Ingredients & Packaging'!$A:$A=B30),0)),0) -> 0 | F30: =IFERROR(C30*E30,0) -> 0 | H30: =IFERROR(F30*(1+G30),0) -> 0
E31: =IFERROR(INDEX('Ingredients & Packaging'!$H:$H, MATCH(1, ('Ingredients & Packaging'!$B:$B=A31)*('Ingredients & Packaging'!$A:$A=B31),0)),0) -> 0 | F31: =IFERROR(C31*E31,0) -> 0 | H31: =IFERROR(F31*(1+G31),0) -> 0
E32: =IFERROR(INDEX('Ingredients & Packaging'!$H:$H, MATCH(1, ('Ingredients & Packaging'!$B:$B=A32)*('Ingredients & Packaging'!$A:$A=B32),0)),0) -> 0 | F32: =IFERROR(C32*E32,0) -> 0 | H32: =IFERROR(F32*(1+G32),0) -> 0
E33: =IFERROR(INDEX('Ingredients & Packaging'!$H:$H, MATCH(1, ('Ingredients & Packaging'!$B:$B=A33)*('Ingredients & Packaging'!$A:$A=B33),0)),0) -> 0 | F33: =IFERROR(C33*E33,0) -> 0 | H33: =IFERROR(F33*(1+G33),0) -> 0
E34: =IFERROR(INDEX('Ingredients & Packaging'!$H:$H, MATCH(1, ('Ingredients & Packaging'!$B:$B=A34)*('Ingredients & Packaging'!$A:$A=B34),0)),0) -> 0 | F34: =IFERROR(C34*E34,0) -> 0 | H34: =IFERROR(F34*(1+G34),0) -> 0
E35: =IFERROR(INDEX('Ingredients & Packaging'!$H:$H, MATCH(1, ('Ingredients & Packaging'!$B:$B=A35)*('Ingredients & Packaging'!$A:$A=B35),0)),0) -> 0 | F35: =IFERROR(C35*E35,0) -> 0 | H35: =IFERROR(F35*(1+G35),0) -> 0
... E56: =IFERROR(INDEX('Ingredients & Packaging'!$H:$H, MATCH(1, ('Ingredients & Packaging'!$B:$B=A56)*('Ingredients & Packaging'!$A:$A=B56),0)),0) -> 0 | F56: =IFERROR(C56*E56,0) -> 0 | H56: =IFERROR(F56*(1+G56),0) -> 0
A58: Cost summary
A59: Total BOM cost (target batch) | B59: =SUM(H17:H56) -> 0
A60: COGS per jar (£) | B60: =IFERROR(B59/ B8,0) -> 0
A61: Target wholesale (£) | B61: =VLOOKUP("MC",'Products Index'!$A:$F,6,FALSE) -> 0
A62: RRP (£) | B62: =VLOOKUP("MC",'Products Index'!$A:$G,7,FALSE) -> 0
A63: Gross margin @ wholesale | B63: =IFERROR((B61-B60)/B61,0) -> 0
...

Sheet Scottish Kimchi (Apple & Kelp)
A1: Scottish Kimchi (Apple & Kelp)
A2: SKU: KIM | Category: Fermented
A4: Product details | E4: Label & marketing fields
A5: Jar size (g) | B5: 190 | E5: Ingredients statement | F5: Chinese leaf cabbage, radish, carrot, spring onion, apple, garlic, ginger, chilli flakes, sea salt, kelp (kombu).
A6: Target batch size (g) | B6: 2200 | E6: Allergen advice | F6: For allergens, see ingredients in bold.
A7: Batch yield actual (g) | B7: 2200 | E7: 3 uses (short) | F7: • Top noodles, rice bowls or fried eggs. • Fold into toasties, burgers or wraps. • Stir into mayo for a quick sandwich sauce.
A8: Units per batch | B8: =IFERROR(B7/B5,0) -> 11.578947 | E8: Recipe idea (short) | F8: Kimchi Fried Rice Fry 1 cup chopped kimchi 2 min. Add 2 cups cold cooked rice; stir-fry hot. Add 2 tbsp kimchi brine (optional). Push aside; scramble 2 eggs (or tofu). Toss and finish with spring onion.
A9: Shelf life unopened | E9: Web product blurb | F9: Crunchy, tangy kimchi with apple sweetness and coastal umami.
A10: Storage instructions
A11: Allergens (bold on label)
A12: Net weight on label | B12: 190
A13: Notes
A15: Bill of Materials (BOM) — per target batch
A16: Component name | B16: Item type | C16: Qty | D16: Unit | E16: Cost/unit (£) | F16: Line cost (£) | G16: Waste % | H16: Cost w/ waste (£) | I16: Supplier/notes
A17: chinese cabbage | E17: =IFERROR(INDEX('Ingredients & Packaging'!$H:$H, MATCH(1, ('Ingredients & Packaging'!$B:$B=A17)*('Ingredients & Packaging'!$A:$A=B17),0)),0) -> 0 | F17: =IFERROR(C17*E17,0) -> 0 | H17: =IFERROR(F17*(1+G17),0) -> 0
A18: radish | E18: =IFERROR(INDEX('Ingredients & Packaging'!$H:$H, MATCH(1, ('Ingredients & Packaging'!$B:$B=A18)*('Ingredients & Packaging'!$A:$A=B18),0)),0) -> 0 | F18: =IFERROR(C18*E18,0) -> 0 | H18: =IFERROR(F18*(1+G18),0) -> 0
A19: carrot | E19: =IFERROR(INDEX('Ingredients & Packaging'!$H:$H, MATCH(1, ('Ingredients & Packaging'!$B:$B=A19)*('Ingredients & Packaging'!$A:$A=B19),0)),0) -> 0 | F19: =IFERROR(C19*E19,0) -> 0 | H19: =IFERROR(F19*(1+G19),0) -> 0
A20: spring onion | E20: =IFERROR(INDEX('Ingredients & Packaging'!$H:$H, MATCH(1, ('Ingredients & Packaging'!$B:$B=A20)*('Ingredients & Packaging'!$A:$A=B20),0)),0) -> 0 | F20: =IFERROR(C20*E20,0) -> 0 | H20: =IFERROR(F20*(1+G20),0) -> 0
A21: apple | E21: =IFERROR(INDEX('Ingredients & Packaging'!$H:$H, MATCH(1, ('Ingredients & Packaging'!$B:$B=A21)*('Ingredients & Packaging'!$A:$A=B21),0)),0) -> 0 | F21: =IFERROR(C21*E21,0) -> 0 | H21: =IFERROR(F21*(1+G21),0) -> 0
A22: garlic | E22: =IFERROR(INDEX('Ingredients & Packaging'!$H:$H, MATCH(1, ('Ingredients & Packaging'!$B:$B=A22)*('Ingredients & Packaging'!$A:$A=B22),0)),0) -> 0 | F22: =IFERROR(C22*E22,0) -> 0 | H22: =IFERROR(F22*(1+G22),0) -> 0
A23: ginger | E23: =IFERROR(INDEX('Ingredients & Packaging'!$H:$H, MATCH(1, ('Ingredients & Packaging'!$B:$B=A23)*('Ingredients & Packaging'!$A:$A=B23),0)),0) -> 0 | F23: =IFERROR(C23*E23,0) -> 0 | H23: =IFERROR(F23*(1+G23),0) -> 0
A24: gochujaru | E24: =IFERROR(INDEX('Ingredients & Packaging'!$H:$H, MATCH(1, ('Ingredients & Packaging'!$B:$B=A24)*('Ingredients & Packaging'!$A:$A=B24),0)),0) -> 0 | F24: =IFERROR(C24*E24,0) -> 0 | H24: =IFERROR(F24*(1+G24),0) -> 0
A25: salt | E25: =IFERROR(INDEX('Ingredients & Packaging'!$H:$H, MATCH(1, ('Ingredients & Packaging'!$B:$B=A25)*('Ingredients & Packaging'!$A:$A=B25),0)),0) -> 0 | F25: =IFERROR(C25*E25,0) -> 0 | H25: =IFERROR(F25*(1+G25),0) -> 0
E26: =IFERROR(INDEX('Ingredients & Packaging'!$H:$H, MATCH(1, ('Ingredients & Packaging'!$B:$B=A26)*('Ingredients & Packaging'!$A:$A=B26),0)),0) -> 0 | F26: =IFERROR(C26*E26,0) -> 0 | H26: =IFERROR(F26*(1+G26),0) -> 0
E27: =IFERROR(INDEX('Ingredients & Packaging'!$H:$H, MATCH(1, ('Ingredients & Packaging'!$B:$B=A27)*('Ingredients & Packaging'!$A:$A=B27),0)),0) -> 0 | F27: =IFERROR(C27*E27,0) -> 0 | H27: =IFERROR(F27*(1+G27),0) -> 0
E28: =IFERROR(INDEX('Ingredients & Packaging'!$H:$H, MATCH(1, ('Ingredients & Packaging'!$B:$B=A28)*('Ingredients & Packaging'!$A:$A=B28),0)),0) -> 0 | F28: =IFERROR(C28*E28,0) -> 0 | H28: =IFERROR(F28*(1+G28),0) -> 0
E29: =IFERROR(INDEX('Ingredients & Packaging'!$H:$H, MATCH(1, ('Ingredients & Packaging'!$B:$B=A29)*('Ingredients & Packaging'!$A:$A=B29),0)),0) -> 0 | F29: =IFERROR(C29*E29,0) -> 0 | H29: =IFERROR(F29*(1+G29),0) -> 0
E30: =IFERROR(INDEX('Ingredients & Packaging'!$H:$H, MATCH(1, ('Ingredients & Packaging'!$B:$B=A30)*('Ingredients & Packaging'!$A:$A=B30),0)),0) -> 0 | F30: =IFERROR(C30*E30,0) -> 0 | H30: =IFERROR(F30*(1+G30),0) -> 0
E31: =IFERROR(INDEX('Ingredients & Packaging'!$H:$H, MATCH(1, ('Ingredients & Packaging'!$B:$B=A31)*('Ingredients & Packaging'!$A:$A=B31),0)),0) -> 0 | F31: =IFERROR(C31*E31,0) -> 0 | H31: =IFERROR(F31*(1+G31),0) -> 0
E32: =IFERROR(INDEX('Ingredients & Packaging'!$H:$H, MATCH(1, ('Ingredients & Packaging'!$B:$B=A32)*('Ingredients & Packaging'!$A:$A=B32),0)),0) -> 0 | F32: =IFERROR(C32*E32,0) -> 0 | H32: =IFERROR(F32*(1+G32),0) -> 0
E33: =IFERROR(INDEX('Ingredients & Packaging'!$H:$H, MATCH(1, ('Ingredients & Packaging'!$B:$B=A33)*('Ingredients & Packaging'!$A:$A=B33),0)),0) -> 0 | F33: =IFERROR(C33*E33,0) -> 0 | H33: =IFERROR(F33*(1+G33),0) -> 0
E34: =IFERROR(INDEX('Ingredients & Packaging'!$H:$H, MATCH(1, ('Ingredients & Packaging'!$B:$B=A34)*('Ingredients & Packaging'!$A:$A=B34),0)),0) -> 0 | F34: =IFERROR(C34*E34,0) -> 0 | H34: =IFERROR(F34*(1+G34),0) -> 0
E35: =IFERROR(INDEX('Ingredients & Packaging'!$H:$H, MATCH(1, ('Ingredients & Packaging'!$B:$B=A35)*('Ingredients & Packaging'!$A:$A=B35),0)),0) -> 0 | F35: =IFERROR(C35*E35,0) -> 0 | H35: =IFERROR(F35*(1+G35),0) -> 0
E36: =IFERROR(INDEX('Ingredients & Packaging'!$H:$H, MATCH(1, ('Ingredients & Packaging'!$B:$B=A36)*('Ingredients & Packaging'!$A:$A=B36),0)),0) -> 0 | F36: =IFERROR(C36*E36,0) -> 0 | H36: =IFERROR(F36*(1+G36),0) -> 0
E37: =IFERROR(INDEX('Ingredients & Packaging'!$H:$H, MATCH(1, ('Ingredients & Packaging'!$B:$B=A37)*('Ingredients & Packaging'!$A:$A=B37),0)),0) -> 0 | F37: =IFERROR(C37*E37,0) -> 0 | H37: =IFERROR(F37*(1+G37),0) -> 0
... E56: =IFERROR(INDEX('Ingredients & Packaging'!$H:$H, MATCH(1, ('Ingredients & Packaging'!$B:$B=A56)*('Ingredients & Packaging'!$A:$A=B56),0)),0) -> 0 | F56: =IFERROR(C56*E56,0) -> 0 | H56: =IFERROR(F56*(1+G56),0) -> 0
A58: Cost summary
A59: Total BOM cost (target batch) | B59: =SUM(H17:H56) -> 0
A60: COGS per jar (£) | B60: =IFERROR(B59/ B8,0) -> 0
A61: Target wholesale (£) | B61: =VLOOKUP("KIM",'Products Index'!$A:$F,6,FALSE) -> 0
...

Sheet Beetroot, Juniper & Black Peppe
A1: Beetroot, Juniper & Black Pepper Sauerkraut
A2: SKU: SK | Category: Fermented
A4: Product details | E4: Label & marketing fields
A5: Jar size (g) | B5: 190 | E5: Ingredients statement | F5: White cabbage, beetroot (20%), juniper berries, black pepper, sea salt.
A6: Target batch size (g) | B6: 2200 | E6: Allergen advice | F6: For allergens, see ingredients in bold.
A7: Batch yield actual (g) | B7: 2200 | E7: 3 uses (short) | F7: • Add to sandwiches, hot dogs or burgers. • Serve with smoked fish, roast pork or sausages. • Toss into salads with apple + dill.
A8: Units per batch | B8: =IFERROR(B7/B5,0) -> 11.578947 | E8: Recipe idea (short) | F8: Reuben‑Style Toastie Layer rye/sourdough with cheese, pastrami (or mushrooms) + mustard. Pan‑toast until melty. Add kraut after to keep it crisp, or warm it briefly first.
A9: Shelf life unopened | E9: Web product blurb | F9: A bright, earthy kraut with juniper lift and peppery bite.
A10: Storage instructions
A11: Allergens (bold on label)
A12: Net weight on label | B12: 190
A13: Notes
A15: Bill of Materials (BOM) — per target batch
A16: Component name | B16: Item type | C16: Qty | D16: Unit | E16: Cost/unit (£) | F16: Line cost (£) | G16: Waste % | H16: Cost w/ waste (£) | I16: Supplier/notes
A17: beetroot | E17: =IFERROR(INDEX('Ingredients & Packaging'!$H:$H, MATCH(1, ('Ingredients & Packaging'!$B:$B=A17)*('Ingredients & Packaging'!$A:$A=B17),0)),0) -> 0 | F17: =IFERROR(C17*E17,0) -> 0 | H17: =IFERROR(F17*(1+G17),0) -> 0
A18: white cabbage | E18: =IFERROR(INDEX('Ingredients & Packaging'!$H:$H, MATCH(1, ('Ingredients & Packaging'!$B:$B=A18)*('Ingredients & Packaging'!$A:$A=B18),0)),0) -> 0 | F18: =IFERROR(C18*E18,0) -> 0 | H18: =IFERROR(F18*(1+G18),0) -> 0
A19: juniper berries | E19: =IFERROR(INDEX('Ingredients & Packaging'!$H:$H, MATCH(1, ('Ingredients & Packaging'!$B:$B=A19)*('Ingredients & Packaging'!$A:$A=B19),0)),0) -> 0 | F19: =IFERROR(C19*E19,0) -> 0 | H19: =IFERROR(F19*(1+G19),0) -> 0
A20: black pepper | E20: =IFERROR(INDEX('Ingredients & Packaging'!$H:$H, MATCH(1, ('Ingredients & Packaging'!$B:$B=A20)*('Ingredients & Packaging'!$A:$A=B20),0)),0) -> 0 | F20: =IFERROR(C20*E20,0) -> 0 | H20: =IFERROR(F20*(1+G20),0) -> 0
A21: sea salt | E21: =IFERROR(INDEX('Ingredients & Packaging'!$H:$H, MATCH(1, ('Ingredients & Packaging'!$B:$B=A21)*('Ingredients & Packaging'!$A:$A=B21),0)),0) -> 0 | F21: =IFERROR(C21*E21,0) -> 0 | H21: =IFERROR(F21*(1+G21),0) -> 0
E22: =IFERROR(INDEX('Ingredients & Packaging'!$H:$H, MATCH(1, ('Ingredients & Packaging'!$B:$B=A22)*('Ingredients & Packaging'!$A:$A=B22),0)),0) -> 0 | F22: =IFERROR(C22*E22,0) -> 0 | H22: =IFERROR(F22*(1+G22),0) -> 0
E23: =IFERROR(INDEX('Ingredients & Packaging'!$H:$H, MATCH(1, ('Ingredients & Packaging'!$B:$B=A23)*('Ingredients & Packaging'!$A:$A=B23),0)),0) -> 0 | F23: =IFERROR(C23*E23,0) -> 0 | H23: =IFERROR(F23*(1+G23),0) -> 0
E24: =IFERROR(INDEX('Ingredients & Packaging'!$H:$H, MATCH(1, ('Ingredients & Packaging'!$B:$B=A24)*('Ingredients & Packaging'!$A:$A=B24),0)),0) -> 0 | F24: =IFERROR(C24*E24,0) -> 0 | H24: =IFERROR(F24*(1+G24),0) -> 0
E25: =IFERROR(INDEX('Ingredients & Packaging'!$H:$H, MATCH(1, ('Ingredients & Packaging'!$B:$B=A25)*('Ingredients & Packaging'!$A:$A=B25),0)),0) -> 0 | F25: =IFERROR(C25*E25,0) -> 0 | H25: =IFERROR(F25*(1+G25),0) -> 0
E26: =IFERROR(INDEX('Ingredients & Packaging'!$H:$H, MATCH(1, ('Ingredients & Packaging'!$B:$B=A26)*('Ingredients & Packaging'!$A:$A=B26),0)),0) -> 0 | F26: =IFERROR(C26*E26,0) -> 0 | H26: =IFERROR(F26*(1+G26),0) -> 0
E27: =IFERROR(INDEX('Ingredients & Packaging'!$H:$H, MATCH(1, ('Ingredients & Packaging'!$B:$B=A27)*('Ingredients & Packaging'!$A:$A=B27),0)),0) -> 0 | F27: =IFERROR(C27*E27,0) -> 0 | H27: =IFERROR(F27*(1+G27),0) -> 0
E28: =IFERROR(INDEX('Ingredients & Packaging'!$H:$H, MATCH(1, ('Ingredients & Packaging'!$B:$B=A28)*('Ingredients & Packaging'!$A:$A=B28),0)),0) -> 0 | F28: =IFERROR(C28*E28,0) -> 0 | H28: =IFERROR(F28*(1+G28),0) -> 0
E29: =IFERROR(INDEX('Ingredients & Packaging'!$H:$H, MATCH(1, ('Ingredients & Packaging'!$B:$B=A29)*('Ingredients & Packaging'!$A:$A=B29),0)),0) -> 0 | F29: =IFERROR(C29*E29,0) -> 0 | H29: =IFERROR(F29*(1+G29),0) -> 0
E30: =IFERROR(INDEX('Ingredients & Packaging'!$H:$H, MATCH(1, ('Ingredients & Packaging'!$B:$B=A30)*('Ingredients & Packaging'!$A:$A=B30),0)),0) -> 0 | F30: =IFERROR(C30*E30,0) -> 0 | H30: =IFERROR(F30*(1+G30),0) -> 0
E31: =IFERROR(INDEX('Ingredients & Packaging'!$H:$H, MATCH(1, ('Ingredients & Packaging'!$B:$B=A31)*('Ingredients & Packaging'!$A:$A=B31),0)),0) -> 0 | F31: =IFERROR(C31*E31,0) -> 0 | H31: =IFERROR(F31*(1+G31),0) -> 0
E32: =IFERROR(INDEX('Ingredients & Packaging'!$H:$H, MATCH(1, ('Ingredients & Packaging'!$B:$B=A32)*('Ingredients & Packaging'!$A:$A=B32),0)),0) -> 0 | F32: =IFERROR(C32*E32,0) -> 0 | H32: =IFERROR(F32*(1+G32),0) -> 0
E33: =IFERROR(INDEX('Ingredients & Packaging'!$H:$H, MATCH(1, ('Ingredients & Packaging'!$B:$B=A33)*('Ingredients & Packaging'!$A:$A=B33),0)),0) -> 0 | F33: =IFERROR(C33*E33,0) -> 0 | H33: =IFERROR(F33*(1+G33),0) -> 0
... E56: =IFERROR(INDEX('Ingredients & Packaging'!$H:$H, MATCH(1, ('Ingredients & Packaging'!$B:$B=A56)*('Ingredients & Packaging'!$A:$A=B56),0)),0) -> 0 | F56: =IFERROR(C56*E56,0) -> 0 | H56: =IFERROR(F56*(1+G56),0) -> 0
A58: Cost summary
A59: Total BOM cost (target batch) | B59: =SUM(H17:H56) -> 0
A60: COGS per jar (£) | B60: =IFERROR(B59/ B8,0) -> 0
A61: Target wholesale (£) | B61: =VLOOKUP("SK",'Products Index'!$A:$F,6,FALSE) -> 0
A62: RRP (£) | B62: =VLOOKUP("SK",'Products Index'!$A:$G,7,FALSE) -> 0
A63: Gross margin @ wholesale | B63: =IFERROR((B61-B60)/B61,0) -> 0
A64: Gross margin @ RRP | B64: =IFERROR((B62-B60)/B62,0) -> 0

Sheet Salted Heather Honey Caramel Sa
A1: Salted Heather Honey Caramel Sauce (Oat)
A2: SKU: HC | Category: Sweet
A4: Product details | E4: Label & marketing fields
A5: Jar size (g) | B5: 190 | E5: Ingredients statement | F5: Sugar, oat milk (OATS), heather honey, vanilla, Scottish sea salt.
A6: Target batch size (g) | B6: 2200 | E6: Allergen advice | F6: For allergens, see ingredients in bold.
A7: Batch yield actual (g) | B7: 2200 | E7: 3 uses (short) | F7: • Drizzle over ice cream, pancakes or porridge. • Stir into coffee/hot chocolate. • Spoon over baked apples or pears.
A8: Units per batch | B8: =IFERROR(B7/B5,0) -> 11.578947 | E8: Recipe idea (short) | F8: Honey‑Salt Sundae Scoop vanilla ice cream. Warm sauce 10–15 sec, drizzle generously. Finish with toasted nuts (optional) and a tiny pinch of flaky salt.
A9: Shelf life unopened | E9: Web product blurb | F9: Silky caramel with heather honey sweetness and a salty finish.
A10: Storage instructions
A11: Allergens (bold on label)
A12: Net weight on label | B12: 190
A13: Notes
A15: Bill of Materials (BOM) — per target batch
A16: Component name | B16: Item type | C16: Qty | D16: Unit | E16: Cost/unit (£) | F16: Line cost (£) | G16: Waste % | H16: Cost w/ waste (£) | I16: Supplier/notes
A17: sugar | E17: =IFERROR(INDEX('Ingredients & Packaging'!$H:$H, MATCH(1, ('Ingredients & Packaging'!$B:$B=A17)*('Ingredients & Packaging'!$A:$A=B17),0)),0) -> 0 | F17: =IFERROR(C17*E17,0) -> 0 | H17: =IFERROR(F17*(1+G17),0) -> 0
A18: oat milk (OATS) | E18: =IFERROR(INDEX('Ingredients & Packaging'!$H:$H, MATCH(1, ('Ingredients & Packaging'!$B:$B=A18)*('Ingredients & Packaging'!$A:$A=B18),0)),0) -> 0 | F18: =IFERROR(C18*E18,0) -> 0 | H18: =IFERROR(F18*(1+G18),0) -> 0
A19: heather honey | E19: =IFERROR(INDEX('Ingredients & Packaging'!$H:$H, MATCH(1, ('Ingredients & Packaging'!$B:$B=A19)*('Ingredients & Packaging'!$A:$A=B19),0)),0) -> 0 | F19: =IFERROR(C19*E19,0) -> 0 | H19: =IFERROR(F19*(1+G19),0) -> 0
A20: vanilla | E20: =IFERROR(INDEX('Ingredients & Packaging'!$H:$H, MATCH(1, ('Ingredients & Packaging'!$B:$B=A20)*('Ingredients & Packaging'!$A:$A=B20),0)),0) -> 0 | F20: =IFERROR(C20*E20,0) -> 0 | H20: =IFERROR(F20*(1+G20),0) -> 0
A21: sea salt | E21: =IFERROR(INDEX('Ingredients & Packaging'!$H:$H, MATCH(1, ('Ingredients & Packaging'!$B:$B=A21)*('Ingredients & Packaging'!$A:$A=B21),0)),0) -> 0 | F21: =IFERROR(C21*E21,0) -> 0 | H21: =IFERROR(F21*(1+G21),0) -> 0
E22: =IFERROR(INDEX('Ingredients & Packaging'!$H:$H, MATCH(1, ('Ingredients & Packaging'!$B:$B=A22)*('Ingredients & Packaging'!$A:$A=B22),0)),0) -> 0 | F22: =IFERROR(C22*E22,0) -> 0 | H22: =IFERROR(F22*(1+G22),0) -> 0
E23: =IFERROR(INDEX('Ingredients & Packaging'!$H:$H, MATCH(1, ('Ingredients & Packaging'!$B:$B=A23)*('Ingredients & Packaging'!$A:$A=B23),0)),0) -> 0 | F23: =IFERROR(C23*E23,0) -> 0 | H23: =IFERROR(F23*(1+G23),0) -> 0
E24: =IFERROR(INDEX('Ingredients & Packaging'!$H:$H, MATCH(1, ('Ingredients & Packaging'!$B:$B=A24)*('Ingredients & Packaging'!$A:$A=B24),0)),0) -> 0 | F24: =IFERROR(C24*E24,0) -> 0 | H24: =IFERROR(F24*(1+G24),0) -> 0
E25: =IFERROR(INDEX('Ingredients & Packaging'!$H:$H, MATCH(1, ('Ingredients & Packaging'!$B:$B=A25)*('Ingredients & Packaging'!$A:$A=B25),0)),0) -> 0 | F25: =IFERROR(C25*E25,0) -> 0 | H25: =IFERROR(F25*(1+G25),0) -> 0
E26: =IFERROR(INDEX('Ingredients & Packaging'!$H:$H, MATCH(1, ('Ingredients & Packaging'!$B:$B=A26)*('Ingredients & Packaging'!$A:$A=B26),0)),0) -> 0 | F26: =IFERROR(C26*E26,0) -> 0 | H26: =IFERROR(F26*(1+G26),0) -> 0
E27: =IFERROR(INDEX('Ingredients & Packaging'!$H:$H, MATCH(1, ('Ingredients & Packaging'!$B:$B=A27)*('Ingredients & Packaging'!$A:$A=B27),0)),0) -> 0 | F27: =IFERROR(C27*E27,0) -> 0 | H27: =IFERROR(F27*(1+G27),0) -> 0
E28: =IFERROR(INDEX('Ingredients & Packaging'!$H:$H, MATCH(1, ('Ingredients & Packaging'!$B:$B=A28)*('Ingredients & Packaging'!$A:$A=B28),0)),0) -> 0 | F28: =IFERROR(C28*E28,0) -> 0 | H28: =IFERROR(F28*(1+G28),0) -> 0
E29: =IFERROR(INDEX('Ingredients & Packaging'!$H:$H, MATCH(1, ('Ingredients & Packaging'!$B:$B=A29)*('Ingredients & Packaging'!$A:$A=B29),0)),0) -> 0 | F29: =IFERROR(C29*E29,0) -> 0 | H29: =IFERROR(F29*(1+G29),0) -> 0
E30: =IFERROR(INDEX('Ingredients & Packaging'!$H:$H, MATCH(1, ('Ingredients & Packaging'!$B:$B=A30)*('Ingredients & Packaging'!$A:$A=B30),0)),0) -> 0 | F30: =IFERROR(C30*E30,0) -> 0 | H30: =IFERROR(F30*(1+G30),0) -> 0
E31: =IFERROR(INDEX('Ingredients & Packaging'!$H:$H, MATCH(1, ('Ingredients & Packaging'!$B:$B=A31)*('Ingredients & Packaging'!$A:$A=B31),0)),0) -> 0 | F31: =IFERROR(C31*E31,0) -> 0 | H31: =IFERROR(F31*(1+G31),0) -> 0
E32: =IFERROR(INDEX('Ingredients & Packaging'!$H:$H, MATCH(1, ('Ingredients & Packaging'!$B:$B=A32)*('Ingredients & Packaging'!$A:$A=B32),0)),0) -> 0 | F32: =IFERROR(C32*E32,0) -> 0 | H32: =IFERROR(F32*(1+G32),0) -> 0
